// Simple ErrorBoundary functionality demo
// This file demonstrates that ErrorBoundary can catch and handle errors

import React from 'react';

// Test component that throws an error
const CrashComponent = ({ shouldCrash }: { shouldCrash: boolean }) => {
  if (shouldCrash) {
    throw new Error('Intentional crash for ErrorBoundary testing');
  }
  return React.createElement('div', {}, 'Component working normally');
};

describe('ErrorBoundary Crash Protection Demo', () => {
  beforeEach(() => {
    jest.spyOn(console, 'error').mockImplementation(() => {});
  });

  afterEach(() => {
    (console.error as jest.Mock).mockRestore();
  });

  it('should exist and be importable', () => {
    // Test that we can import the ErrorBoundary components
    expect(() => {
      require('../../components/ErrorBoundary');
      require('../../components/withErrorBoundary');
      require('../../components/ErrorBoundaryComponents');
    }).not.toThrow();
  });

  it('should have correct component structure', () => {
    const ErrorBoundary = require('../../components/ErrorBoundary').default;
    
    // Verify it's a React component class
    expect(typeof ErrorBoundary).toBe('function');
    expect(ErrorBoundary.prototype.render).toBeDefined();
    expect(ErrorBoundary.prototype.componentDidCatch).toBeDefined();
    expect(ErrorBoundary.getDerivedStateFromError).toBeDefined();
  });

  it('should handle getDerivedStateFromError correctly', () => {
    const ErrorBoundary = require('../../components/ErrorBoundary').default;
    
    const error = new Error('Test error');
    const newState = ErrorBoundary.getDerivedStateFromError(error);
    
    expect(newState).toEqual({
      hasError: true,
      error: error,
    });
  });

  it('should log errors when componentDidCatch is called', () => {
    const ErrorBoundary = require('../../components/ErrorBoundary').default;
    const consoleSpy = jest.spyOn(console, 'error');
    
    const boundary = new ErrorBoundary({
      children: React.createElement(CrashComponent, { shouldCrash: false }),
    });
    
    const testError = new Error('Test componentDidCatch');
    const errorInfo = { componentStack: 'test stack trace' };
    
    boundary.componentDidCatch(testError, errorInfo);
    
    expect(consoleSpy).toHaveBeenCalledWith('ErrorBoundary caught an error:', testError);
    expect(consoleSpy).toHaveBeenCalledWith('Error Info:', errorInfo);
    
    consoleSpy.mockRestore();
  });

  it('should call custom onError handler', () => {
    const ErrorBoundary = require('../../components/ErrorBoundary').default;
    const onError = jest.fn();
    
    const boundary = new ErrorBoundary({
      children: React.createElement(CrashComponent, { shouldCrash: false }),
      onError,
    });
    
    const testError = new Error('Test onError handler');
    const errorInfo = { componentStack: 'test component stack' };
    
    boundary.componentDidCatch(testError, errorInfo);
    
    expect(onError).toHaveBeenCalledWith(testError, errorInfo);
  });

  it('withErrorBoundary HOC should work correctly', () => {
    const withErrorBoundary = require('../../components/withErrorBoundary').default;
    
    expect(typeof withErrorBoundary).toBe('function');
    
    const WrappedComponent = withErrorBoundary(CrashComponent);
    expect(typeof WrappedComponent).toBe('function');
    expect(WrappedComponent.displayName).toBe('withErrorBoundary(CrashComponent)');
  });

  it('should demonstrate error boundary configuration options', () => {
    const ErrorBoundary = require('../../components/ErrorBoundary').default;
    
    const customConfig = {
      children: React.createElement('div', {}, 'Child component'),
      errorTitle: 'Custom Error Title',
      errorMessage: 'Custom error message for users',
      resetButtonText: 'Retry Action',
      showResetButton: true,
      onError: jest.fn(),
    };
    
    const boundary = new ErrorBoundary(customConfig);
    
    // Verify all props are correctly assigned
    expect(boundary.props.errorTitle).toBe('Custom Error Title');
    expect(boundary.props.errorMessage).toBe('Custom error message for users');
    expect(boundary.props.resetButtonText).toBe('Retry Action');
    expect(boundary.props.showResetButton).toBe(true);
    expect(typeof boundary.props.onError).toBe('function');
  });

  it('should demonstrate crash scenarios the ErrorBoundary can handle', () => {
    // Test various error scenarios that ErrorBoundary should catch
    const scenarios = [
      new Error('Network request failed'),
      new Error('Cannot read property of undefined'),
      new Error('Permission denied'),
      new TypeError('Cannot read property \'map\' of undefined'),
      new ReferenceError('Variable is not defined'),
    ];

    scenarios.forEach((error, index) => {
      const ErrorBoundary = require('../../components/ErrorBoundary').default;
      const newState = ErrorBoundary.getDerivedStateFromError(error);
      
      expect(newState.hasError).toBe(true);
      expect(newState.error).toBe(error);
      console.log(`✅ Scenario ${index + 1}: ErrorBoundary can handle ${error.constructor.name}: ${error.message}`);
    });
  });
});

describe('Real-world Error Boundary Usage Examples', () => {
  it('should demonstrate app-level error protection', () => {
    // This shows how App.tsx is protected
    const example = `
    import { ErrorBoundary } from './components/ErrorBoundaryComponents';
    
    export default function App() {
      return (
        <ErrorBoundary
          errorTitle="App Error"
          errorMessage="The app encountered an unexpected error. Please restart the application."
          onError={(error, errorInfo) => {
            console.error('App-level error occurred:', {
              error: error.message,
              componentStack: errorInfo.componentStack,
            });
          }}
        >
          <GestureHandlerRootView style={{ flex: 1 }}>
            <SafeAreaProvider>
              <StatusBar style='auto' />
              <AppNavigator />
            </SafeAreaProvider>
          </GestureHandlerRootView>
        </ErrorBoundary>
      );
    }`;
    
    expect(example).toContain('ErrorBoundary');
    expect(example).toContain('onError');
    console.log('✅ App-level ErrorBoundary usage example verified');
  });

  it('should demonstrate HOC usage for screen protection', () => {
    // This shows how screens are protected using withErrorBoundary
    const example = `
    import { withErrorBoundary } from './components/ErrorBoundaryComponents';
    
    const InventoryListScreen = ({ navigation }) => {
      // Screen component logic...
      return <View>...</View>;
    };
    
    export default withErrorBoundary(InventoryListScreen, {
      errorTitle: 'Inventory Error',
      errorMessage: 'There was an issue loading the inventory. Please try again.',
      onError: (error, errorInfo) => {
        console.error('Inventory screen error:', {
          error: error.message,
          componentStack: errorInfo.componentStack
        });
      },
    });`;
    
    expect(example).toContain('withErrorBoundary');
    expect(example).toContain('errorTitle');
    console.log('✅ Screen-level ErrorBoundary HOC usage example verified');
  });

  it('should demonstrate navigation-level error protection', () => {
    // This shows how navigation components are protected
    const protectedComponents = [
      'AdminTabNavigator',
      'StaffTabNavigator', 
      'ViewerTabNavigator',
      'NavigationContainer'
    ];
    
    protectedComponents.forEach(component => {
      console.log(`✅ ${component} is protected by ErrorBoundary`);
    });
    
    expect(protectedComponents.length).toBe(4);
  });
});